<sdf version='1.6'>
  <world name='default'>
    <light name='sun' type='directional'>
      <cast_shadows>1</cast_shadows>
      <pose frame=''>0 0 10 0 -0 0</pose>
      <diffuse>0.8 0.8 0.8 1</diffuse>
      <specular>0.1 0.1 0.1 1</specular>
      <attenuation>
        <range>1000</range>
        <constant>0.9</constant>
        <linear>0.01</linear>
        <quadratic>0.001</quadratic>
      </attenuation>
      <direction>-0.5 0.5 -1</direction>
    </light>
    <model name='ground_plane'>
      <static>1</static>
      <link name='link'>
        <collision name='collision'>
          <geometry>
            <plane>
              <normal>0 0 1</normal>
              <size>100 100</size>
            </plane>
          </geometry>
          <surface>
            <friction>
              <ode>
                <mu>100</mu>
                <mu2>50</mu2>
              </ode>
              <torsional>
                <ode/>
              </torsional>
            </friction>
            <contact>
              <ode/>
            </contact>
            <bounce/>
          </surface>
          <max_contacts>10</max_contacts>
        </collision>
        <visual name='visual'>
          <cast_shadows>0</cast_shadows>
          <geometry>
            <plane>
              <normal>0 0 1</normal>
              <size>100 100</size>
            </plane>
          </geometry>
          <material>
            <script>
              <uri>file://media/materials/scripts/gazebo.material</uri>
              <name>Gazebo/Grey</name>
            </script>
          </material>
        </visual>
        <self_collide>0</self_collide>
        <kinematic>0</kinematic>
        <gravity>1</gravity>
      </link>
    </model>
    <gravity>0 0 -9.8</gravity>
    <magnetic_field>6e-06 2.3e-05 -4.2e-05</magnetic_field>
    <atmosphere type='adiabatic'/>
    <physics name='default_physics' default='0' type='ode'>
      <max_step_size>0.001</max_step_size>
      <real_time_factor>1</real_time_factor>
      <real_time_update_rate>1000</real_time_update_rate>
    </physics>
    <scene>
      <ambient>0.4 0.4 0.4 1</ambient>
      <background>0.7 0.7 0.7 1</background>
      <shadows>1</shadows>
    </scene>
    <spherical_coordinates>
      <surface_model>EARTH_WGS84</surface_model>
      <latitude_deg>0</latitude_deg>
      <longitude_deg>0</longitude_deg>
      <elevation>0</elevation>
      <heading_deg>0</heading_deg>
    </spherical_coordinates>
    <model name='cafe'>
      <static>1</static>
      <link name='link'>
        <collision name='main_floor'>
          <pose frame=''>-0.4 -0.75 0.0948 0 -0 0</pose>
          <geometry>
            <box>
              <size>9.38 22.63 0.19</size>
            </box>
          </geometry>
          <max_contacts>10</max_contacts>
          <surface>
            <contact>
              <ode/>
            </contact>
            <bounce/>
            <friction>
              <torsional>
                <ode/>
              </torsional>
              <ode/>
            </friction>
          </surface>
        </collision>
        <collision name='wall_1'>
          <pose frame=''>-5.03 0.53 1.415 0 -0 0</pose>
          <geometry>
            <box>
              <size>0.12 23.16 2.83</size>
            </box>
          </geometry>
          <max_contacts>10</max_contacts>
          <surface>
            <contact>
              <ode/>
            </contact>
            <bounce/>
            <friction>
              <torsional>
                <ode/>
              </torsional>
              <ode/>
            </friction>
          </surface>
        </collision>
        <collision name='wall_2'>
          <pose frame=''>4.24 -0.31 1.415 0 -0 0</pose>
          <geometry>
            <box>
              <size>0.12 21.48 2.83</size>
            </box>
          </geometry>
          <max_contacts>10</max_contacts>
          <surface>
            <contact>
              <ode/>
            </contact>
            <bounce/>
            <friction>
              <torsional>
                <ode/>
              </torsional>
              <ode/>
            </friction>
          </surface>
        </collision>
        <collision name='wall_3'>
          <pose frame=''>-1.48 7.43 1.415 0 -0 0</pose>
          <geometry>
            <box>
              <size>7.2 0.12 2.83</size>
            </box>
          </geometry>
          <max_contacts>10</max_contacts>
          <surface>
            <contact>
              <ode/>
            </contact>
            <bounce/>
            <friction>
              <torsional>
                <ode/>
              </torsional>
              <ode/>
            </friction>
          </surface>
        </collision>
        <collision name='wall_4'>
          <pose frame=''>2.09 8.9 1.435 0 -0 0</pose>
          <geometry>
            <box>
              <size>0.12 3.05 2.87</size>
            </box>
          </geometry>
          <max_contacts>10</max_contacts>
          <surface>
            <contact>
              <ode/>
            </contact>
            <bounce/>
            <friction>
              <torsional>
                <ode/>
              </torsional>
              <ode/>
            </friction>
          </surface>
        </collision>
        <collision name='wall_5'>
          <pose frame=''>3.155 10.4 1.435 0 -0 0</pose>
          <geometry>
            <box>
              <size>2.13 0.12 2.87</size>
            </box>
          </geometry>
          <max_contacts>10</max_contacts>
          <surface>
            <contact>
              <ode/>
            </contact>
            <bounce/>
            <friction>
              <torsional>
                <ode/>
              </torsional>
              <ode/>
            </friction>
          </surface>
        </collision>
        <collision name='wall_6'>
          <pose frame=''>0.615 -10.98 1.415 0 -0 0</pose>
          <geometry>
            <box>
              <size>7.36 0.15 2.83</size>
            </box>
          </geometry>
          <max_contacts>10</max_contacts>
          <surface>
            <contact>
              <ode/>
            </contact>
            <bounce/>
            <friction>
              <torsional>
                <ode/>
              </torsional>
              <ode/>
            </friction>
          </surface>
        </collision>
        <collision name='wall_7'>
          <pose frame=''>-4.62 -10.98 1.415 0 -0 0</pose>
          <geometry>
            <box>
              <size>0.93 0.15 2.83</size>
            </box>
          </geometry>
          <max_contacts>10</max_contacts>
          <surface>
            <contact>
              <ode/>
            </contact>
            <bounce/>
            <friction>
              <torsional>
                <ode/>
              </torsional>
              <ode/>
            </friction>
          </surface>
        </collision>
        <collision name='wall_8'>
          <pose frame=''>-3.61 -10.98 2.69 0 -0 0</pose>
          <geometry>
            <box>
              <size>1.09 0.15 0.28</size>
            </box>
          </geometry>
          <max_contacts>10</max_contacts>
          <surface>
            <contact>
              <ode/>
            </contact>
            <bounce/>
            <friction>
              <torsional>
                <ode/>
              </torsional>
              <ode/>
            </friction>
          </surface>
        </collision>
        <collision name='coke'>
          <pose frame=''>-4.385 0.26 0.95 0 -0 0</pose>
          <geometry>
            <box>
              <size>1.03 1.03 1.52</size>
            </box>
          </geometry>
          <max_contacts>10</max_contacts>
          <surface>
            <contact>
              <ode/>
            </contact>
            <bounce/>
            <friction>
              <torsional>
                <ode/>
              </torsional>
              <ode/>
            </friction>
          </surface>
        </collision>
        <visual name='visual'>
          <geometry>
            <mesh>
              <uri>model://cafe/meshes/cafe.dae</uri>
              <scale>1 1 1</scale>
            </mesh>
          </geometry>
        </visual>
        <self_collide>0</self_collide>
        <kinematic>0</kinematic>
        <gravity>1</gravity>
      </link>
      <pose frame=''>1.23108 -0.158716 0 0 -0 0</pose>
    </model>
    <state world_name='default'>
      <sim_time>94 217000000</sim_time>
      <real_time>35 552502269</real_time>
      <wall_time>1638587335 415010419</wall_time>
      <iterations>34843</iterations>
      <model name='cafe'>
        <pose frame=''>1.23108 -0.158716 0 0 -0 0</pose>
        <scale>1 1 1</scale>
        <link name='link'>
          <pose frame=''>1.23108 -0.158716 0 0 -0 0</pose>
          <velocity>0 0 0 0 -0 0</velocity>
          <acceleration>0 0 0 0 -0 0</acceleration>
          <wrench>0 0 0 0 -0 0</wrench>
        </link>
      </model>
      <model name='ground_plane'>
        <pose frame=''>0 0 0 0 -0 0</pose>
        <scale>1 1 1</scale>
        <link name='link'>
          <pose frame=''>0 0 0 0 -0 0</pose>
          <velocity>0 0 0 0 -0 0</velocity>
          <acceleration>0 0 0 0 -0 0</acceleration>
          <wrench>0 0 0 0 -0 0</wrench>
        </link>
      </model>
      <model name='mbot'>
        <pose frame=''>-0.070305 0.141694 0.189796 2.1e-05 -0 -0.121554</pose>
        <scale>1 1 1</scale>
        <link name='back_caster_link'>
          <pose frame=''>0.108367 0.11987 0.204796 0.001158 -1.27617 -0.122663</pose>
          <velocity>0.000192 0.001456 -0.004209 -0.043814 0.004907 -1.6e-05</velocity>
          <acceleration>0.208423 1.53767 -4.38263 2.89902 -0.497067 -0.005042</acceleration>
          <wrench>0.104212 0.768837 -2.19132 0 -0 0</wrench>
        </link>
        <link name='base_footprint'>
          <pose frame=''>-0.070305 0.141694 0.189796 2.1e-05 -0 -0.121554</pose>
          <velocity>0.000315 0.002453 -0.004255 0.034537 -0.004297 -1.6e-05</velocity>
          <acceleration>-0.321747 -2.66651 -4.12132 0.014787 0.115739 -0.005053</acceleration>
          <wrench>-6.46712 -53.5969 -82.8385 0 -0 0</wrench>
        </link>
        <link name='front_caster_link'>
          <pose frame=''>-0.248976 0.163522 0.204796 0.000368 -0.436109 -0.12171</pose>
          <velocity>0.000193 0.001466 -0.00424 -0.04307 0.005813 1.2e-05</velocity>
          <acceleration>0.194986 1.54688 -4.41498 -2.58693 -0.594458 0.028072</acceleration>
          <wrench>0.097493 0.773439 -2.20749 0 -0 0</wrench>
        </link>
        <link name='left_wheel_link'>
          <pose frame=''>-0.093343 -0.046904 0.249792 5e-05 -0.063495 -0.121556</pose>
          <velocity>3.8e-05 0.000253 -0.010919 0.027422 -0.003428 -0.000249</velocity>
          <acceleration>-0.006743 -0.099598 -13.7226 1.75286 -0.093742 1.62083</acceleration>
          <wrench>-0.013485 -0.199197 -27.4452 0 -0 0</wrench>
        </link>
        <link name='right_wheel_link'>
          <pose frame=''>-0.047267 0.330289 0.2498 -7e-05 -0.1136 -0.121551</pose>
          <velocity>-1.4e-05 -0.000171 0.00245 0.002853 -0.000308 -0.001749</velocity>
          <acceleration>-0.12594 -0.99931 5.67412 -2.27457 -0.393941 -2.30943</acceleration>
          <wrench>-0.251879 -1.99862 11.3482 0 -0 0</wrench>
        </link>
      </model>
      <model name='unit_box_0'>
        <pose frame=''>-0.538336 -6.52854 0.6898 0 -0 0</pose>
        <scale>1 1 1</scale>
        <link name='link'>
          <pose frame=''>-0.538336 -6.52854 0.6898 0 -0 0</pose>
          <velocity>0 0 0 0 -0 0</velocity>
          <acceleration>0 0 0 0 -0 0</acceleration>
          <wrench>0 0 0 0 -0 0</wrench>
        </link>
      </model>
      <model name='unit_cylinder_0'>
        <pose frame=''>2.2456 -3.18081 0.68979 1e-06 -0 1.2e-05</pose>
        <scale>1 1 1</scale>
        <link name='link'>
          <pose frame=''>2.2456 -3.18081 0.68979 1e-06 -0 1.2e-05</pose>
          <velocity>0 0 0 0 -0 0</velocity>
          <acceleration>0 0 -9.8 0 -0 0</acceleration>
          <wrench>0 0 -9.8 0 -0 0</wrench>
        </link>
      </model>
      <light name='sun'>
        <pose frame=''>0 0 10 0 -0 0</pose>
      </light>
    </state>
    <gui fullscreen='0'>
      <camera name='user_camera'>
        <pose frame=''>11.0302 4.34349 46.6818 0 1.33164 -2.14299</pose>
        <view_controller>orbit</view_controller>
        <projection_type>perspective</projection_type>
      </camera>
    </gui>
    <model name='mbot'>
      <link name='base_footprint'>
        <pose frame=''>0 0 0 0 -0 0</pose>
        <inertial>
          <pose frame=''>0 0 0.110522 0 -0 0</pose>
          <mass>20.1</mass>
          <inertia>
            <ixx>0.253764</ixx>
            <ixy>0</ixy>
            <ixz>0</ixz>
            <iyy>0.253764</iyy>
            <iyz>0</iyz>
            <izz>0.41</izz>
          </inertia>
        </inertial>
        <collision name='base_footprint_fixed_joint_lump__base_link_collision'>
          <pose frame=''>0 0 0.11 0 -0 0</pose>
          <geometry>
            <cylinder>
              <length>0.16</length>
              <radius>0.2</radius>
            </cylinder>
          </geometry>
          <surface>
            <contact>
              <ode/>
            </contact>
            <friction>
              <ode/>
              <torsional>
                <ode/>
              </torsional>
            </friction>
            <bounce/>
          </surface>
          <max_contacts>10</max_contacts>
        </collision>
        <collision name='base_footprint_fixed_joint_lump__laser_link_collision_1'>
          <pose frame=''>0 0 0.215 0 -0 0</pose>
          <geometry>
            <cylinder>
              <length>0.06</length>
              <radius>0.05</radius>
            </cylinder>
          </geometry>
          <surface>
            <contact>
              <ode/>
            </contact>
            <friction>
              <ode/>
              <torsional>
                <ode/>
              </torsional>
            </friction>
            <bounce/>
          </surface>
          <max_contacts>10</max_contacts>
        </collision>
        <visual name='base_footprint_visual'>
          <pose frame=''>0 0 0 0 -0 0</pose>
          <geometry>
            <box>
              <size>0.001 0.001 0.001</size>
            </box>
          </geometry>
          <material>
            <script>
              <uri>__default__</uri>
              <name>__default__</name>
            </script>
          </material>
        </visual>
        <visual name='base_footprint_fixed_joint_lump__base_link_visual_1'>
          <pose frame=''>0 0 0.11 0 -0 0</pose>
          <geometry>
            <cylinder>
              <length>0.16</length>
              <radius>0.2</radius>
            </cylinder>
          </geometry>
          <material>
            <script>
              <name>Gazebo/Blue</name>
              <uri>file://media/materials/scripts/gazebo.material</uri>
            </script>
          </material>
        </visual>
        <visual name='base_footprint_fixed_joint_lump__laser_link_visual_2'>
          <pose frame=''>0 0 0.215 0 -0 0</pose>
          <geometry>
            <cylinder>
              <length>0.05</length>
              <radius>0.05</radius>
            </cylinder>
          </geometry>
          <material>
            <script>
              <name>Gazebo/Black</name>
              <uri>file://media/materials/scripts/gazebo.material</uri>
            </script>
          </material>
        </visual>
        <velocity_decay/>
        <velocity_decay/>
        <velocity_decay/>
        <gravity>1</gravity>
        <velocity_decay/>
        <self_collide>0</self_collide>
        <sensor name='rplidar' type='ray'>
          <visualize>0</visualize>
          <update_rate>5.5</update_rate>
          <ray>
            <scan>
              <horizontal>
                <samples>360</samples>
                <resolution>1</resolution>
                <min_angle>-3</min_angle>
                <max_angle>3</max_angle>
              </horizontal>
              <vertical>
                <samples>1</samples>
                <min_angle>0</min_angle>
                <max_angle>0</max_angle>
              </vertical>
            </scan>
            <range>
              <min>0.1</min>
              <max>6</max>
              <resolution>0.01</resolution>
            </range>
            <noise>
              <type>gaussian</type>
              <mean>0</mean>
              <stddev>0.01</stddev>
            </noise>
          </ray>
          <plugin name='gazebo_rplidar' filename='libgazebo_ros_laser.so'>
            <topicName>/scan</topicName>
            <frameName>laser_link</frameName>
            <robotNamespace>/</robotNamespace>
          </plugin>
          <pose frame=''>0 0 0.215 0 -0 0</pose>
        </sensor>
        <kinematic>0</kinematic>
      </link>
      <link name='back_caster_link'>
        <pose frame=''>0.18 0 0.015 0 -0 0</pose>
        <inertial>
          <pose frame=''>0 0 0 0 -0 0</pose>
          <mass>0.5</mass>
          <inertia>
            <ixx>4.5e-05</ixx>
            <ixy>0</ixy>
            <ixz>0</ixz>
            <iyy>4.5e-05</iyy>
            <iyz>0</iyz>
            <izz>4.5e-05</izz>
          </inertia>
        </inertial>
        <collision name='back_caster_link_collision'>
          <pose frame=''>0 0 0 0 -0 0</pose>
          <geometry>
            <sphere>
              <radius>0.015</radius>
            </sphere>
          </geometry>
          <surface>
            <contact>
              <ode/>
            </contact>
            <friction>
              <ode/>
              <torsional>
                <ode/>
              </torsional>
            </friction>
            <bounce/>
          </surface>
          <max_contacts>10</max_contacts>
        </collision>
        <visual name='back_caster_link_visual'>
          <pose frame=''>0 0 0 0 -0 0</pose>
          <geometry>
            <sphere>
              <radius>0.015</radius>
            </sphere>
          </geometry>
          <material>
            <script>
              <name>Gazebo/Black</name>
              <uri>file://media/materials/scripts/gazebo.material</uri>
            </script>
          </material>
        </visual>
        <gravity>1</gravity>
        <velocity_decay/>
        <self_collide>0</self_collide>
        <kinematic>0</kinematic>
      </link>
      <joint name='back_caster_joint' type='revolute'>
        <child>back_caster_link</child>
        <parent>base_footprint</parent>
        <axis>
          <xyz>0 1 0</xyz>
          <limit>
            <lower>-1e+16</lower>
            <upper>1e+16</upper>
          </limit>
          <dynamics>
            <spring_reference>0</spring_reference>
            <spring_stiffness>0</spring_stiffness>
          </dynamics>
          <use_parent_model_frame>1</use_parent_model_frame>
        </axis>
      </joint>
      <link name='front_caster_link'>
        <pose frame=''>-0.18 0 0.015 0 -0 0</pose>
        <inertial>
          <pose frame=''>0 0 0 0 -0 0</pose>
          <mass>0.5</mass>
          <inertia>
            <ixx>4.5e-05</ixx>
            <ixy>0</ixy>
            <ixz>0</ixz>
            <iyy>4.5e-05</iyy>
            <iyz>0</iyz>
            <izz>4.5e-05</izz>
          </inertia>
        </inertial>
        <collision name='front_caster_link_collision'>
          <pose frame=''>0 0 0 0 -0 0</pose>
          <geometry>
            <sphere>
              <radius>0.015</radius>
            </sphere>
          </geometry>
          <surface>
            <contact>
              <ode/>
            </contact>
            <friction>
              <ode/>
              <torsional>
                <ode/>
              </torsional>
            </friction>
            <bounce/>
          </surface>
          <max_contacts>10</max_contacts>
        </collision>
        <visual name='front_caster_link_visual'>
          <pose frame=''>0 0 0 0 -0 0</pose>
          <geometry>
            <sphere>
              <radius>0.015</radius>
            </sphere>
          </geometry>
          <material>
            <script>
              <name>Gazebo/Black</name>
              <uri>file://media/materials/scripts/gazebo.material</uri>
            </script>
          </material>
        </visual>
        <gravity>1</gravity>
        <velocity_decay/>
        <self_collide>0</self_collide>
        <kinematic>0</kinematic>
      </link>
      <joint name='front_caster_joint' type='revolute'>
        <child>front_caster_link</child>
        <parent>base_footprint</parent>
        <axis>
          <xyz>0 1 0</xyz>
          <limit>
            <lower>-1e+16</lower>
            <upper>1e+16</upper>
          </limit>
          <dynamics>
            <spring_reference>0</spring_reference>
            <spring_stiffness>0</spring_stiffness>
          </dynamics>
          <use_parent_model_frame>1</use_parent_model_frame>
        </axis>
      </joint>
      <link name='left_wheel_link'>
        <pose frame=''>0 -0.19 0.06 0 -0 0</pose>
        <inertial>
          <pose frame=''>0 0 0 0 -0 0</pose>
          <mass>2</mass>
          <inertia>
            <ixx>0.00190417</ixx>
            <ixy>0</ixy>
            <ixz>0</ixz>
            <iyy>0.00190417</iyy>
            <iyz>0</iyz>
            <izz>0.0036</izz>
          </inertia>
        </inertial>
        <collision name='left_wheel_link_collision'>
          <pose frame=''>0 0 0 1.5708 -0 0</pose>
          <geometry>
            <cylinder>
              <length>0.025</length>
              <radius>0.06</radius>
            </cylinder>
          </geometry>
          <surface>
            <contact>
              <ode/>
            </contact>
            <friction>
              <ode/>
              <torsional>
                <ode/>
              </torsional>
            </friction>
            <bounce/>
          </surface>
          <max_contacts>10</max_contacts>
        </collision>
        <visual name='left_wheel_link_visual'>
          <pose frame=''>0 0 0 1.5708 -0 0</pose>
          <geometry>
            <cylinder>
              <length>0.025</length>
              <radius>0.06</radius>
            </cylinder>
          </geometry>
          <material>
            <script>
              <name>Gazebo/Gray</name>
              <uri>file://media/materials/scripts/gazebo.material</uri>
            </script>
          </material>
        </visual>
        <gravity>1</gravity>
        <velocity_decay/>
        <self_collide>0</self_collide>
        <kinematic>0</kinematic>
      </link>
      <joint name='left_wheel_joint' type='revolute'>
        <child>left_wheel_link</child>
        <parent>base_footprint</parent>
        <axis>
          <xyz>0 1 0</xyz>
          <limit>
            <lower>-1e+16</lower>
            <upper>1e+16</upper>
          </limit>
          <dynamics>
            <spring_reference>0</spring_reference>
            <spring_stiffness>0</spring_stiffness>
          </dynamics>
          <use_parent_model_frame>1</use_parent_model_frame>
        </axis>
      </joint>
      <link name='right_wheel_link'>
        <pose frame=''>0 0.19 0.06 0 -0 0</pose>
        <inertial>
          <pose frame=''>0 0 0 0 -0 0</pose>
          <mass>2</mass>
          <inertia>
            <ixx>0.00190417</ixx>
            <ixy>0</ixy>
            <ixz>0</ixz>
            <iyy>0.00190417</iyy>
            <iyz>0</iyz>
            <izz>0.0036</izz>
          </inertia>
        </inertial>
        <collision name='right_wheel_link_collision'>
          <pose frame=''>0 0 0 1.5708 -0 0</pose>
          <geometry>
            <cylinder>
              <length>0.025</length>
              <radius>0.06</radius>
            </cylinder>
          </geometry>
          <surface>
            <contact>
              <ode/>
            </contact>
            <friction>
              <ode/>
              <torsional>
                <ode/>
              </torsional>
            </friction>
            <bounce/>
          </surface>
          <max_contacts>10</max_contacts>
        </collision>
        <visual name='right_wheel_link_visual'>
          <pose frame=''>0 0 0 1.5708 -0 0</pose>
          <geometry>
            <cylinder>
              <length>0.025</length>
              <radius>0.06</radius>
            </cylinder>
          </geometry>
          <material>
            <script>
              <name>Gazebo/Gray</name>
              <uri>file://media/materials/scripts/gazebo.material</uri>
            </script>
          </material>
        </visual>
        <gravity>1</gravity>
        <velocity_decay/>
        <self_collide>0</self_collide>
        <kinematic>0</kinematic>
      </link>
      <joint name='right_wheel_joint' type='revolute'>
        <child>right_wheel_link</child>
        <parent>base_footprint</parent>
        <axis>
          <xyz>0 1 0</xyz>
          <limit>
            <lower>-1e+16</lower>
            <upper>1e+16</upper>
          </limit>
          <dynamics>
            <spring_reference>0</spring_reference>
            <spring_stiffness>0</spring_stiffness>
          </dynamics>
          <use_parent_model_frame>1</use_parent_model_frame>
        </axis>
      </joint>
      <static>0</static>
      <plugin name='differential_drive_controller' filename='libgazebo_ros_diff_drive.so'>
        <rosDebugLevel>Debug</rosDebugLevel>
        <publishWheelTF>true</publishWheelTF>
        <robotNamespace>/</robotNamespace>
        <publishTf>1</publishTf>
        <publishWheelJointState>true</publishWheelJointState>
        <alwaysOn>true</alwaysOn>
        <updateRate>100.0</updateRate>
        <legacyMode>true</legacyMode>
        <leftJoint>left_wheel_joint</leftJoint>
        <rightJoint>right_wheel_joint</rightJoint>
        <wheelSeparation>0.38</wheelSeparation>
        <wheelDiameter>0.12</wheelDiameter>
        <broadcastTF>1</broadcastTF>
        <wheelTorque>30</wheelTorque>
        <wheelAcceleration>1.8</wheelAcceleration>
        <commandTopic>cmd_vel</commandTopic>
        <odometryFrame>odom</odometryFrame>
        <odometryTopic>odom</odometryTopic>
        <robotBaseFrame>base_footprint</robotBaseFrame>
      </plugin>
      <pose frame=''>0 0 0 0 -0 0</pose>
    </model>
    <model name='unit_box_0'>
      <pose frame=''>-0.538336 -6.52854 0.5 0 -0 0</pose>
      <link name='link'>
        <inertial>
          <mass>1</mass>
          <inertia>
            <ixx>0.166667</ixx>
            <ixy>0</ixy>
            <ixz>0</ixz>
            <iyy>0.166667</iyy>
            <iyz>0</iyz>
            <izz>0.166667</izz>
          </inertia>
        </inertial>
        <collision name='collision'>
          <geometry>
            <box>
              <size>1 1 1</size>
            </box>
          </geometry>
          <max_contacts>10</max_contacts>
          <surface>
            <contact>
              <ode/>
            </contact>
            <bounce/>
            <friction>
              <torsional>
                <ode/>
              </torsional>
              <ode/>
            </friction>
          </surface>
        </collision>
        <visual name='visual'>
          <geometry>
            <box>
              <size>1 1 1</size>
            </box>
          </geometry>
          <material>
            <script>
              <name>Gazebo/Grey</name>
              <uri>file://media/materials/scripts/gazebo.material</uri>
            </script>
          </material>
        </visual>
        <self_collide>0</self_collide>
        <kinematic>0</kinematic>
        <gravity>1</gravity>
      </link>
    </model>
    <model name='unit_cylinder_0'>
      <pose frame=''>2.2456 -3.18081 0.5 0 -0 0</pose>
      <link name='link'>
        <inertial>
          <mass>1</mass>
          <inertia>
            <ixx>0.145833</ixx>
            <ixy>0</ixy>
            <ixz>0</ixz>
            <iyy>0.145833</iyy>
            <iyz>0</iyz>
            <izz>0.125</izz>
          </inertia>
        </inertial>
        <collision name='collision'>
          <geometry>
            <cylinder>
              <radius>0.5</radius>
              <length>1</length>
            </cylinder>
          </geometry>
          <max_contacts>10</max_contacts>
          <surface>
            <contact>
              <ode/>
            </contact>
            <bounce/>
            <friction>
              <torsional>
                <ode/>
              </torsional>
              <ode/>
            </friction>
          </surface>
        </collision>
        <visual name='visual'>
          <geometry>
            <cylinder>
              <radius>0.5</radius>
              <length>1</length>
            </cylinder>
          </geometry>
          <material>
            <script>
              <name>Gazebo/Grey</name>
              <uri>file://media/materials/scripts/gazebo.material</uri>
            </script>
          </material>
        </visual>
        <self_collide>0</self_collide>
        <kinematic>0</kinematic>
        <gravity>1</gravity>
      </link>
    </model>
  </world>
</sdf>
